// Error handling
fn main() {
    // panic!("Terrible Error"); // To create an unexpected error and quit
    let lil_arr = [1, 2];
    // println!("{}", lil_arr[10]); // Will throw an error
}
